{"uuid": "245985da-20e8-4309-875f-58802bd9cdf2", "children": ["91870adb-96fe-47fd-926f-1601198064cf", "bbd22658-f5a5-4a48-9ec7-120cd70c801c", "7b192794-062f-4803-ae7f-d7c649fa0b21", "49f3b897-5344-405b-b902-fd11ba35d655", "19d41df3-4063-4c71-a062-67b82577b8d9", "e6032554-a473-44c2-98aa-53cb36e3279b", "f2c67fe0-3c1e-4c57-a7e3-d73327dca1a4", "33b34a99-dcdd-4986-8bde-4b478fa101da", "6a532104-0602-41ff-847c-85e74f99c826", "d5235f16-5ab1-4829-b413-f6a1b5e37bf1", "a6c588a1-a1f1-40d3-9399-5757138bba9c", "01365b11-ac0d-4a62-a627-1088b5e51657", "03d121ec-b332-4987-b4b6-d45a702d9eba"], "befores": [{"name": "fix_module", "status": "broken", "statusDetails": {"message": "requests.exceptions.ConnectionError: HTTPConnectionPool(host='www.base.com', port=80): Max retries exceeded with url: /test/user/login (Caused by NewConnectionError('<urllib3.connection.HTTPConnection object at 0x000002497D32A630>: Failed to establish a new connection: [WinError 10060] 由于连接方在一段时间后没有正确答复或连接的主机没有反应，连接尝试失败。'))\n", "trace": "  File \"C:\\Users\\Admin\\AppData\\Local\\Programs\\Python\\Python37\\lib\\site-packages\\pluggy\\callers.py\", line 187, in _multicall\n    res = hook_impl.function(*args)\n  File \"C:\\Users\\Admin\\AppData\\Local\\Programs\\Python\\Python37\\lib\\site-packages\\_pytest\\fixtures.py\", line 964, in pytest_fixture_setup\n    result = call_fixture_func(fixturefunc, request, kwargs)\n  File \"C:\\Users\\Admin\\AppData\\Local\\Programs\\Python\\Python37\\lib\\site-packages\\_pytest\\fixtures.py\", line 788, in call_fixture_func\n    res = next(it)\n  File \"D:\\allure_demo\\conftest.py\", line 58, in fix_module\n    fix_login_res = login(app_cof.MOBILE, app_cof.PASSWORD, env_url=app_cof.BASE_URL)\n  File \"C:\\Users\\Admin\\AppData\\Local\\Programs\\Python\\Python37\\lib\\site-packages\\allure_commons\\_allure.py\", line 172, in impl\n    return func(*a, **kw)\n  File \"D:\\allure_demo\\report_demo\\pages\\funcs.py\", line 19, in login\n    login_res = case_data.request_handle.required('post', url=url, data=data, headers=headers)\n  File \"D:\\allure_demo\\report_demo\\utils\\request_handle.py\", line 20, in required\n    res = requests.post(url=url, data=data, headers=headers)\n  File \"C:\\Users\\Admin\\AppData\\Local\\Programs\\Python\\Python37\\lib\\site-packages\\requests\\api.py\", line 119, in post\n    return request('post', url, data=data, json=json, **kwargs)\n  File \"C:\\Users\\Admin\\AppData\\Local\\Programs\\Python\\Python37\\lib\\site-packages\\requests\\api.py\", line 61, in request\n    return session.request(method=method, url=url, **kwargs)\n  File \"C:\\Users\\Admin\\AppData\\Local\\Programs\\Python\\Python37\\lib\\site-packages\\requests\\sessions.py\", line 542, in request\n    resp = self.send(prep, **send_kwargs)\n  File \"C:\\Users\\Admin\\AppData\\Local\\Programs\\Python\\Python37\\lib\\site-packages\\requests\\sessions.py\", line 655, in send\n    r = adapter.send(request, **kwargs)\n  File \"C:\\Users\\Admin\\AppData\\Local\\Programs\\Python\\Python37\\lib\\site-packages\\requests\\adapters.py\", line 516, in send\n    raise ConnectionError(e, request=request)\n"}, "steps": [{"name": "登录", "status": "broken", "statusDetails": {"message": "requests.exceptions.ConnectionError: HTTPConnectionPool(host='www.base.com', port=80): Max retries exceeded with url: /test/user/login (Caused by NewConnectionError('<urllib3.connection.HTTPConnection object at 0x000002497D32A630>: Failed to establish a new connection: [WinError 10060] 由于连接方在一段时间后没有正确答复或连接的主机没有反应，连接尝试失败。'))\n", "trace": "  File \"C:\\Users\\Admin\\AppData\\Local\\Programs\\Python\\Python37\\lib\\site-packages\\allure_commons\\_allure.py\", line 172, in impl\n    return func(*a, **kw)\n  File \"D:\\allure_demo\\report_demo\\pages\\funcs.py\", line 19, in login\n    login_res = case_data.request_handle.required('post', url=url, data=data, headers=headers)\n  File \"D:\\allure_demo\\report_demo\\utils\\request_handle.py\", line 20, in required\n    res = requests.post(url=url, data=data, headers=headers)\n  File \"C:\\Users\\Admin\\AppData\\Local\\Programs\\Python\\Python37\\lib\\site-packages\\requests\\api.py\", line 119, in post\n    return request('post', url, data=data, json=json, **kwargs)\n  File \"C:\\Users\\Admin\\AppData\\Local\\Programs\\Python\\Python37\\lib\\site-packages\\requests\\api.py\", line 61, in request\n    return session.request(method=method, url=url, **kwargs)\n  File \"C:\\Users\\Admin\\AppData\\Local\\Programs\\Python\\Python37\\lib\\site-packages\\requests\\sessions.py\", line 542, in request\n    resp = self.send(prep, **send_kwargs)\n  File \"C:\\Users\\Admin\\AppData\\Local\\Programs\\Python\\Python37\\lib\\site-packages\\requests\\sessions.py\", line 655, in send\n    r = adapter.send(request, **kwargs)\n  File \"C:\\Users\\Admin\\AppData\\Local\\Programs\\Python\\Python37\\lib\\site-packages\\requests\\adapters.py\", line 516, in send\n    raise ConnectionError(e, request=request)\n"}, "parameters": [{"name": "mobile", "value": "17802156123"}, {"name": "password", "value": "123456"}, {"name": "env_url", "value": "'http://www.base.com'"}], "start": 1617500441651, "stop": 1617500463944}], "start": 1617500441650, "stop": 1617500464000}], "start": 1617500441650, "stop": 1617500465739}