{"uuid": "8080aed4-83d1-47c7-8780-6183ce6456e9", "children": ["711342e6-901e-4adf-a9c8-cc4f451e5439", "17221c4d-495c-47e1-a958-cbe38a119663", "53fe5934-54ae-41e2-8856-242cd4a0a387", "6dc98fc4-92f4-4163-888f-c1622d8acc6a", "2af49c71-30dc-4136-9b04-91323f063718", "058a3ec6-dbff-4706-8c89-009131687087", "da3d42d6-b567-4894-b509-67e3bfd49b43", "e9522ba8-1c21-4bf3-bf06-3d4bebe5579c", "f64320cb-b752-4ae4-8230-20a102ca1b6d", "7debabdb-f364-4b47-9d66-3b993552ec9c", "0a717e77-ce02-465a-9958-f7ec5502c595", "6075cbc6-84f9-444a-998e-80566de72cff", "8b0e5260-ed29-4291-93c9-90ffe1e3f384"], "befores": [{"name": "fix_module", "status": "passed", "steps": [{"name": "调用登陆接口", "status": "passed", "parameters": [{"name": "mobile", "value": "17802156123"}, {"name": "password", "value": "123456"}, {"name": "env_url", "value": "'http://www.niuinfo.com'"}], "start": 1619690903753, "stop": 1619690904040}], "start": 1619690903753, "stop": 1619690904051}], "afters": [{"name": "fix_module::0", "status": "broken", "statusDetails": {"message": "kombu.exceptions.OperationalError: Error 10061 connecting to 127.0.0.1:6379. 由于目标计算机积极拒绝，无法连接。.\n", "trace": "  File \"C:\\Users\\luban\\AppData\\Local\\Programs\\Python\\Python37\\lib\\site-packages\\allure_commons\\_allure.py\", line 200, in __call__\n    return self._fixture_function(*args, **kwargs)\n  File \"C:\\Users\\luban\\AppData\\Local\\Programs\\Python\\Python37\\lib\\site-packages\\_pytest\\fixtures.py\", line 941, in _teardown_yield_fixture\n    next(it)\n  File \"F:\\api_base\\conftest.py\", line 75, in fix_module\n    execute_command.delay()\n  File \"C:\\Users\\luban\\AppData\\Local\\Programs\\Python\\Python37\\lib\\site-packages\\celery\\app\\task.py\", line 421, in delay\n    return self.apply_async(args, kwargs)\n  File \"C:\\Users\\luban\\AppData\\Local\\Programs\\Python\\Python37\\lib\\site-packages\\celery\\app\\task.py\", line 565, in apply_async\n    **options\n  File \"C:\\Users\\luban\\AppData\\Local\\Programs\\Python\\Python37\\lib\\site-packages\\celery\\app\\base.py\", line 749, in send_task\n    amqp.send_task_message(P, name, message, **options)\n  File \"C:\\Users\\luban\\AppData\\Local\\Programs\\Python\\Python37\\lib\\contextlib.py\", line 130, in __exit__\n    self.gen.throw(type, value, traceback)\n  File \"C:\\Users\\luban\\AppData\\Local\\Programs\\Python\\Python37\\lib\\site-packages\\kombu\\connection.py\", line 452, in _reraise_as_library_errors\n    raise ConnectionError(str(exc)) from exc\n"}, "start": 1619690905108, "stop": 1619690968938}], "start": 1619690903753, "stop": 1619690968938}