{"uuid": "353c2b60-fd0d-4ad1-a34e-ee9a91f23f78", "children": ["ee6e0ac8-7a15-478c-a836-b573b796295c", "5ffe5348-ec43-47e6-8e78-03cf7729bd7f", "cc7774fe-6a32-4b46-8b4e-9180393ec38c", "fe3cb113-b720-42d0-b1e2-9b5f3caf184e", "0ff7ede2-bcde-4e61-bd13-b2385a12c3c3", "90e6fb74-a214-4e40-a83c-eed2fd398cea", "bf8ecf77-0871-4458-9aab-be4ad174326b", "cda3f346-c3b8-4f12-8016-9c5c6db8f266", "d8bee03e-197c-4a7d-be01-42715e9e925e", "e0bcad04-3a68-4d82-8002-81a43b270492", "c2735e20-004f-45cc-99bf-ae3b019ef8b7", "55825055-f4b5-49f1-8fd9-1ba3715a97ec", "30517a7c-3a00-4220-9bc2-da9edd6cfcd1"], "befores": [{"name": "fix_module", "status": "passed", "steps": [{"name": "调用登陆接口", "status": "passed", "parameters": [{"name": "mobile", "value": "17802156123"}, {"name": "password", "value": "123456"}, {"name": "env_url", "value": "'http://www.niuinfo.com'"}], "start": 1619691139721, "stop": 1619691139896}], "start": 1619691139721, "stop": 1619691139897}], "afters": [{"name": "fix_module::0", "status": "broken", "statusDetails": {"message": "kombu.exceptions.OperationalError: Error 10061 connecting to 127.0.0.1:6379. 由于目标计算机积极拒绝，无法连接。.\n", "trace": "  File \"C:\\Users\\luban\\AppData\\Local\\Programs\\Python\\Python37\\lib\\site-packages\\allure_commons\\_allure.py\", line 200, in __call__\n    return self._fixture_function(*args, **kwargs)\n  File \"C:\\Users\\luban\\AppData\\Local\\Programs\\Python\\Python37\\lib\\site-packages\\_pytest\\fixtures.py\", line 941, in _teardown_yield_fixture\n    next(it)\n  File \"F:\\api_base\\conftest.py\", line 75, in fix_module\n    execute_command.delay()\n  File \"C:\\Users\\luban\\AppData\\Local\\Programs\\Python\\Python37\\lib\\site-packages\\celery\\app\\task.py\", line 421, in delay\n    return self.apply_async(args, kwargs)\n  File \"C:\\Users\\luban\\AppData\\Local\\Programs\\Python\\Python37\\lib\\site-packages\\celery\\app\\task.py\", line 565, in apply_async\n    **options\n  File \"C:\\Users\\luban\\AppData\\Local\\Programs\\Python\\Python37\\lib\\site-packages\\celery\\app\\base.py\", line 749, in send_task\n    amqp.send_task_message(P, name, message, **options)\n  File \"C:\\Users\\luban\\AppData\\Local\\Programs\\Python\\Python37\\lib\\contextlib.py\", line 130, in __exit__\n    self.gen.throw(type, value, traceback)\n  File \"C:\\Users\\luban\\AppData\\Local\\Programs\\Python\\Python37\\lib\\site-packages\\kombu\\connection.py\", line 452, in _reraise_as_library_errors\n    raise ConnectionError(str(exc)) from exc\n"}, "start": 1619691140974, "stop": 1619691204812}], "start": 1619691139721, "stop": 1619691204813}